Workbook
Name Acumulación: '[1]Entrevista Balance'!$D$17
Name Acumulación: 'Entrevista Balance'!$D$17
Name Afore: '[1]Entrevista Balance'!$D$24
Name Afore: 'Entrevista Balance'!$D$24
Name CapacidaddeAhorro: '[1]Entrevista Balance'!$G$28
Name CapacidaddeAhorro: 'Entrevista Balance'!$G$28
Name CapitalHumanoPotencialVF: 'Cálculos y Supuestos Balance'!$C$25
Name CapitalHumanoPotencialVP: 'Cálculos y Supuestos Balance'!$C$24
Name CapRatePropiedades: 'Cálculos y Supuestos Balance'!$C$5
Name CoberturaCortoPlazo: 'Cálculos y Supuestos Balance'!$I$5
Name CostoSegurodeVidaporMillón: 'Cálculos y Supuestos Balance'!$C$6
Name DependientesEconómicos: 'Entrevista Balance'!$D$10
Name EdadActual: 'Entrevista Balance'!$D$6
Name EdadActual: 'Entrevista Balance'!$D$6
Name EdadActual: 'Entrevista Balance'!$D$6
Name EdadActual: 'Cálculos y Supuestos Edo.Res'!$C$7
Name EdadActual2: 'Cálculos y Supuestos Edo.Res'!$C$7
Name EdaddeDefunción: '[1]Cálculos y Supuestos Balance'!$C$4
Name EdaddeDefunción: 'Cálculos y Supuestos Balance'!$C$4
Name EdaddeRetiro: '[1]Entrevista Balance'!$D$34
Name EdaddeRetiro: 'Entrevista Balance'!$D$34
Name FinRecursos: '[1]Cálculos y Supuestos Edo.Res'!$C$9
Name FinRecursos: 'Cálculos y Supuestos Edo.Res'!$C$9
Name IngresosPrincipales: 'Cálculos y Supuestos Balance'!$C$9
Name InicioDesacumulacion: '[1]Cálculos y Supuestos Edo.Res'!$C$8
Name InicioDesacumulacion: 'Cálculos y Supuestos Edo.Res'!$C$8
Name MensualidaddeseadaenelRetiro: '[1]Entrevista Balance'!$D$36
Name MensualidaddeseadaenelRetiro: 'Entrevista Balance'!$D$36
Name MiNivel: 'Cálculos y Supuestos Balance'!$I$22
Name MLey73: '[1]Entrevista Balance'!$D$32
Name MLey73: 'Entrevista Balance'!$D$32
Name Montoaproximadodeinversión: '[1]Cálculos y Supuestos Balance'!$T$21
Name Montoaproximadodeinversión: 'Cálculos y Supuestos Balance'!$T$21
Name Númerodeperiodosacumulación: '[1]Cálculos y Supuestos Balance'!$C$23
Name Númerodeperiodosacumulación: 'Cálculos y Supuestos Balance'!$C$23
Name Númerodeperiodosdesacumulación: 'Cálculos y Supuestos Balance'!$C$20
Name OtrosIngresos: '[1]Entrevista Balance'!$G$32
Name OtrosIngresos: 'Entrevista Balance'!$G$32
Name OtrosPlanesdeSegurosparaRetiro: '[1]Entrevista Balance'!$D$30
Name OtrosPlanesdeSegurosparaRetiro: 'Entrevista Balance'!$D$30
Name PatrimonioFinancieroActualTotal: '[1]Cálculos y Supuestos Balance'!$C$22
Name PatrimonioFinancieroActualTotal: 'Cálculos y Supuestos Balance'!$C$22
Name PatrimonioFinancieroActualTotalVF: '[1]Cálculos y Supuestos Balance'!$C$34
Name PatrimonioFinancieroActualTotalVF: 'Cálculos y Supuestos Balance'!$C$34
Name PlanesdeSeguroAcumulación1: '[1]Entrevista Balance'!$D$19
Name PlanesdeSeguroAcumulación1: 'Entrevista Balance'!$D$19
Name PlanPrivadodePensión: '[1]Entrevista Balance'!$D$28
Name PlanPrivadodePensión: 'Entrevista Balance'!$D$28
Name Plazo2: 'Entrevista Balance'!$D$22
Name PPR: '[1]Entrevista Balance'!$D$26
Name PPR: 'Entrevista Balance'!$D$26
Name Rentas: '[1]Entrevista Balance'!$G$30
Name Rentas: 'Entrevista Balance'!$G$30
Name ReservaCortoPlazo: '[1]Entrevista Balance'!$D$15
Name ReservaCortoPlazo: 'Entrevista Balance'!$D$15
Name Saldoenesquemasderetiro: 'Cálculos y Supuestos Balance'!$C$10
Name SumaAseguradadeSegurodeVida: 'Cálculos y Supuestos Balance'!$C$81
Name TasaReal: 'Cálculos y Supuestos Balance'!$C$3
Name TasaReal: 'Cálculos y Supuestos Balance'!$C$3
Name TasaReal: '[1]Cálculos y Supuestos Edo.Res'!$C$4

Sheet Entrevista Patrimonio F.
O2: =TODAY() -> 46083
C3: Asesor:
C5: GENERALES DE CLIENTE
D7: Nombre o alias: | E7: JUAN PEREZ | L7: ID Cliente/Prospecto:
L8: *Llenado por el asesor
D9: Edad actual: | E9: 50 | G9: Género: | I9: Hombre
G11: Ocupación actual: | I11: Asalariado
C15: La siguiente información es necesaria para calcular tu fortaleza financiera.
C17: INGRESOS MENSUALES | K17: OBLIGACIONES MENSUALES
D19: ¿Cuál es tu capacidad de Ahorro? | I19: 50000 | L19: ¿A cuánto ascienden tus gastos básicos mensuales? | P19: 40000
L20: Alimentos, servicios, transporte, ropa, entretenimiento, pago de renta
D21: ¿Tienes ingresos mensuales por propiedades en rentas? | I21: 10000 | L21: ¿A cuánto ascienden tus obligaciones mensuales? | P21: 20000
L22: Colegiaturas, seguros, manutención, impuestos. *Sin considerar créditos | R22: Institución:
D23: ¿Cuál es el monto mensual de otros ingresos? | I23: 0 | L23: ¿A cuánto ascienden créditos? | P23: 0
C27: PATRIMONIO FINANCIERO
N28: Institución:
D29: ¿Cuál es el monto de tus los ahorros de los que puedes disponer de forma inmediata? | L29: 200000
D30: Saldo en cuentas de débito o instrumentos de liquidez inmediata
D31: ¿A cuánto asciende tu saldo en otras inversiones financieras? | L31: 2000000
D32: Inversiones financieras no líquidas
D33: ¿Cuál es el saldo otros planes de seguro de acumulación? | L33: 100000
D34: Dotales
D36: ¿A qué edad planeas retirarte? | G36: 60 | L36: ESQUEMAS DE RETIRO
R37: Institución:
D38: ¿Cuánto deseas percibir mensualmente en tu edad de retiro? | I38: 50000 | L38: ¿Cuál es el saldo de tu cuenta de Afore? | P38: 1000000
L40: ¿Cuál es el saldo en tu PPR? | P40: 0
L42: ¿Cuál es el saldo en Plan privado de pensión? | P42: 0
L44: ¿Cuál es el saldo otros planes de seguro para el retiro? | P44: 0
L46: ¿Cuál es tu mensualidad aproximada por la Ley 73? | P46: 35000
L47: Solo para mayores de 46 años que cotizaron antes del 1o de julio de 1997. Aplica Ley 73
C50: La siguiente información es necesaria para diagnosticar el valor de tu patrimonio en riesgo.
C52: PROTECCIÓN PATRIMONIAL
Y53: =IF(Y52<>"",IF(Y52+1>80,"",Y52+1),"")
D54: ¿Tienes dependientes económicos? | G54: Sí | Y54: =IF(Y53<>"",IF(Y53+1>80,"",Y53+1),"")
Y55: =IF(Y54<>"",IF(Y54+1>80,"",Y54+1),"")
D56: ¿Tus propiedades están aseguradas? | G56: No | Y56: =IF(Y55<>"",IF(Y55+1>80,"",Y55+1),"")
Y57: =IF(Y56<>"",IF(Y56+1>80,"",Y56+1),"")

Sheet Cálculos y Supuestos Edo.Res
W2: Regla del 72
W3: Total | X3: ='Entrevista Patrimonio F.'!L29+'Entrevista Patrimonio F.'!L31 -> 2200000
B4: Tasa Real | C4: 0.01
M5: =(72/M6)/100 -> 9 | N5: =(72/N6)/100 -> 6 | O5: =(72/O6)/100 -> 5.1428571
B6: Información General | F6: Análisis Ingreso/Gasto | L6: Periodo | M6: 0.08 | N6: 0.12 | O6: 0.14 | R6: Años | S6: 0.08 | T6: 0.12 | U6: 0.14 | X6: 0.08 | Y6: 0.12 | Z6: 0.14
B7: Edad | C7: ='Entrevista Patrimonio F.'!E9 -> 50 | L7: 1 | M7: =ROUND(M$5*$L7,0) -> 9 | N7: =ROUND(N$5*$L7,0) -> 6 | O7: =ROUND(O$5*$L7,0) -> 5 | P7: =L7 -> 1 | R7: 0 | S7: =MAX(IFERROR(VLOOKUP($R7,$M$7:$P$17,4,0),0)+1,S6) -> 1 | T7: =MAX(IFERROR(VLOOKUP($R7,$N$7:$P$17,3,0),0)+1,T6) -> 1 | U7: =MAX(IFERROR(VLOOKUP($R7,$O$7:$P$17,2,0),0)+1,U6) -> 1 | W7: 0 | X7: =1*$X$3 -> 2200000 | Y7: =1*$X$3 -> 2200000 | Z7: =1*$X$3 -> 2200000
B8: Edad de Retiro | C8: ='Entrevista Patrimonio F.'!G36 -> 60 | F8: Output 1 | L8: 2 | M8: =ROUND(M$5*$L8,0) -> 18 | N8: =ROUND(N$5*$L8,0) -> 12 | O8: =ROUND(O$5*$L8,0) -> 10 | P8: =L8 -> 2 | R8: =R7+1 -> 1 | S8: =MAX(IFERROR(VLOOKUP($R8,$M$7:$P$17,4,0),0)+1,S7) -> 1 | T8: =MAX(IFERROR(VLOOKUP($R8,$N$7:$P$17,3,0),0)+1,T7) -> 1 | U8: =MAX(IFERROR(VLOOKUP($R8,$O$7:$P$17,2,0),0)+1,U7) -> 1 | W8: =W7+1 -> 1
B9: Longevidad recursos (Edad Individuo) | C9: 90 | L9: 3 | M9: =ROUND(M$5*$L9,0) -> 27 | N9: =ROUND(N$5*$L9,0) -> 18 | O9: =ROUND(O$5*$L9,0) -> 15 | P9: =L9 -> 3 | R9: =R8+1 -> 2 | S9: =MAX(IFERROR(VLOOKUP($R9,$M$7:$P$17,4,0),0)+1,S8) -> 1 | T9: =MAX(IFERROR(VLOOKUP($R9,$N$7:$P$17,3,0),0)+1,T8) -> 1 | U9: =MAX(IFERROR(VLOOKUP($R9,$O$7:$P$17,2,0),0)+1,U8) -> 1 | W9: =W8+1 -> 2
B10: Genero | C10: ='Entrevista Patrimonio F.'!I9 -> Hombre | F10: Capacidad de Ahorro | G10: ='Entrevista Patrimonio F.'!I19 -> 50000 | H10: =G10/$C$19 -> 0.45454545 | L10: 4 | M10: =ROUND(M$5*$L10,0) -> 36 | N10: =ROUND(N$5*$L10,0) -> 24 | O10: =ROUND(O$5*$L10,0) -> 21 | P10: =L10 -> 4 | R10: =R9+1 -> 3 | S10: =MAX(IFERROR(VLOOKUP($R10,$M$7:$P$17,4,0),0)+1,S9) -> 1 | T10: =MAX(IFERROR(VLOOKUP($R10,$N$7:$P$17,3,0),0)+1,T9) -> 1 | U10: =MAX(IFERROR(VLOOKUP($R10,$O$7:$P$17,2,0),0)+1,U9) -> 1 | W10: =W9+1 -> 3
B11: Dependientes Economicos | C11: ='Entrevista Patrimonio F.'!G54 -> Sí | F11: Capacidad de Ahorro Anual | G11: =G10*12 -> 600000 | L11: 5 | M11: =ROUND(M$5*$L11,0) -> 45 | N11: =ROUND(N$5*$L11,0) -> 30 | O11: =ROUND(O$5*$L11,0) -> 26 | P11: =L11 -> 5 | R11: =R10+1 -> 4 | S11: =MAX(IFERROR(VLOOKUP($R11,$M$7:$P$17,4,0),0)+1,S10) -> 1 | T11: =MAX(IFERROR(VLOOKUP($R11,$N$7:$P$17,3,0),0)+1,T10) -> 1 | U11: =MAX(IFERROR(VLOOKUP($R11,$O$7:$P$17,2,0),0)+1,U10) -> 1 | W11: =W10+1 -> 4
B12: Profesion Actual | C12: ='Entrevista Patrimonio F.'!I11 -> Asalariado | F12: Output 2 | L12: 6 | M12: =ROUND(M$5*$L12,0) -> 54 | N12: =ROUND(N$5*$L12,0) -> 36 | O12: =ROUND(O$5*$L12,0) -> 31 | P12: =L12 -> 6 | R12: =R11+1 -> 5 | S12: =MAX(IFERROR(VLOOKUP($R12,$M$7:$P$17,4,0),0)+1,S11) -> 1 | T12: =MAX(IFERROR(VLOOKUP($R12,$N$7:$P$17,3,0),0)+1,T11) -> 1 | U12: =MAX(IFERROR(VLOOKUP($R12,$O$7:$P$17,2,0),0)+1,U11) -> 2 | W12: =W11+1 -> 5 | Z12: =2*$X$3 -> 4400000
B13: Calidad de Vida Retiro | C13: ='Entrevista Patrimonio F.'!I38 -> 50000 | F13: Benchmark Reserva CP | G13: 3 | H13: Gastos Básicos | L13: 7 | N13: =ROUND(N$5*$L13,0) -> 42 | O13: =ROUND(O$5*$L13,0) -> 36 | P13: =L13 -> 7 | R13: =R12+1 -> 6 | S13: =MAX(IFERROR(VLOOKUP($R13,$M$7:$P$17,4,0),0)+1,S12) -> 1 | T13: =MAX(IFERROR(VLOOKUP($R13,$N$7:$P$17,3,0),0)+1,T12) -> 2 | U13: =MAX(IFERROR(VLOOKUP($R13,$O$7:$P$17,2,0),0)+1,U12) -> 2 | W13: =W12+1 -> 6 | Y13: =2*$X$3 -> 4400000
F14: Reserva Deseada CP | G14: =C22*G13 -> 120000 | L14: 8 | N14: =ROUND(N$5*$L14,0) -> 48 | O14: =ROUND(O$5*$L14,0) -> 41 | P14: =L14 -> 8 | R14: =R13+1 -> 7 | S14: =MAX(IFERROR(VLOOKUP($R14,$M$7:$P$17,4,0),0)+1,S13) -> 1 | T14: =MAX(IFERROR(VLOOKUP($R14,$N$7:$P$17,3,0),0)+1,T13) -> 2 | U14: =MAX(IFERROR(VLOOKUP($R14,$O$7:$P$17,2,0),0)+1,U13) -> 2 | W14: =W13+1 -> 7
B15: Ingresos | F15: Meses de Reserva CP | G15: =C29/C22 -> 5 | L15: 9 | N15: =ROUND(N$5*$L15,0) -> 54 | O15: =ROUND(O$5*$L15,0) -> 46 | P15: =L15 -> 9 | R15: =R14+1 -> 8 | S15: =MAX(IFERROR(VLOOKUP($R15,$M$7:$P$17,4,0),0)+1,S14) -> 1 | T15: =MAX(IFERROR(VLOOKUP($R15,$N$7:$P$17,3,0),0)+1,T14) -> 2 | U15: =MAX(IFERROR(VLOOKUP($R15,$O$7:$P$17,2,0),0)+1,U14) -> 2 | W15: =W14+1 -> 8
B16: Ingresos Básicos | C16: ='Entrevista Patrimonio F.'!P19+'Entrevista Patrimonio F.'!P21+'Entrevista Patrimonio F.'!P23+'Entrevista Patrimonio F.'!I19-'Entrevista Patrimonio F.'!I21-'Entrevista Patrimonio F.'!I23 -> 100000 | F16: Resultado | G16: =IF(G15>=G13,"Excedido","Insuficiente") -> Excedido | L16: 10 | O16: =ROUND(O$5*$L16,0) -> 51 | P16: =L16 -> 10 | R16: =R15+1 -> 9 | S16: =MAX(IFERROR(VLOOKUP($R16,$M$7:$P$17,4,0),0)+1,S15) -> 2 | T16: =MAX(IFERROR(VLOOKUP($R16,$N$7:$P$17,3,0),0)+1,T15) -> 2 | U16: =MAX(IFERROR(VLOOKUP($R16,$O$7:$P$17,2,0),0)+1,U15) -> 2 | W16: =W15+1 -> 9 | X16: =2*$X$3 -> 4400000
B17: Propiedades en Renta | C17: ='Entrevista Patrimonio F.'!I21 -> 10000 | F17: Pendiente por Ahorrar | G17: =IF(G16="Insuficiente",G14-C29,0) -> 0 | L17: 11 | P17: =L17 -> 11 | R17: =R16+1 -> 10 | S17: =MAX(IFERROR(VLOOKUP($R17,$M$7:$P$17,4,0),0)+1,S16) -> 2 | T17: =MAX(IFERROR(VLOOKUP($R17,$N$7:$P$17,3,0),0)+1,T16) -> 2 | U17: =MAX(IFERROR(VLOOKUP($R17,$O$7:$P$17,2,0),0)+1,U16) -> 3 | W17: =W16+1 -> 10 | Z17: =4*$X$3 -> 8800000
B18: Otros Ingresos | C18: ='Entrevista Patrimonio F.'!I23 -> 0 | F18: Meses para cubrir CP | G18: =IFERROR(IF(G17=0,0,(G17/G10)),0) -> 0 | R18: =R17+1 -> 11 | S18: =MAX(IFERROR(VLOOKUP($R18,$M$7:$P$17,4,0),0)+1,S17) -> 2 | T18: =MAX(IFERROR(VLOOKUP($R18,$N$7:$P$17,3,0),0)+1,T17) -> 2 | U18: =MAX(IFERROR(VLOOKUP($R18,$O$7:$P$17,2,0),0)+1,U17) -> 3 | W18: =W17+1 -> 11
B19: Ingresos Totales | C19: =SUM(C16:C18) -> 110000 | F19: Remanente para otros objetivos | G19: =MAX(G10*(1-G18),0) -> 50000 | R19: =R18+1 -> 12 | S19: =MAX(IFERROR(VLOOKUP($R19,$M$7:$P$17,4,0),0)+1,S18) -> 2 | T19: =MAX(IFERROR(VLOOKUP($R19,$N$7:$P$17,3,0),0)+1,T18) -> 3 | U19: =MAX(IFERROR(VLOOKUP($R19,$O$7:$P$17,2,0),0)+1,U18) -> 3 | W19: =W18+1 -> 12 | Y19: =4*$X$3 -> 8800000
R20: =R19+1 -> 13 | S20: =MAX(IFERROR(VLOOKUP($R20,$M$7:$P$17,4,0),0)+1,S19) -> 2 | T20: =MAX(IFERROR(VLOOKUP($R20,$N$7:$P$17,3,0),0)+1,T19) -> 3 | U20: =MAX(IFERROR(VLOOKUP($R20,$O$7:$P$17,2,0),0)+1,U19) -> 3 | W20: =W19+1 -> 13
B21: Gastos Básicos + Obligaciones | F21: Output 3 | R21: =R20+1 -> 14 | S21: =MAX(IFERROR(VLOOKUP($R21,$M$7:$P$17,4,0),0)+1,S20) -> 2 | T21: =MAX(IFERROR(VLOOKUP($R21,$N$7:$P$17,3,0),0)+1,T20) -> 3 | U21: =MAX(IFERROR(VLOOKUP($R21,$O$7:$P$17,2,0),0)+1,U20) -> 3 | W21: =W20+1 -> 14
B22: Gastos Básicos | C22: ='Entrevista Patrimonio F.'!P19 -> 40000 | F22: Saldo Acumulación | G22: =(C30+C35) -> 2100000 | R22: =R21+1 -> 15 | S22: =MAX(IFERROR(VLOOKUP($R22,$M$7:$P$17,4,0),0)+1,S21) -> 2 | T22: =MAX(IFERROR(VLOOKUP($R22,$N$7:$P$17,3,0),0)+1,T21) -> 3 | U22: =MAX(IFERROR(VLOOKUP($R22,$O$7:$P$17,2,0),0)+1,U21) -> 4 | W22: =W21+1 -> 15 | Z22: =8*$X$3 -> 17600000
B23: Gastos Básicos | C23: =C22 -> 40000 | D23: =C23/$C$19 -> 0.36363636 | F23: Meses de Reserva Acumulación | G23: =(G22/C26)/12 -> 2.9166667 | R23: =R22+1 -> 16 | S23: =MAX(IFERROR(VLOOKUP($R23,$M$7:$P$17,4,0),0)+1,S22) -> 2 | T23: =MAX(IFERROR(VLOOKUP($R23,$N$7:$P$17,3,0),0)+1,T22) -> 3 | U23: =MAX(IFERROR(VLOOKUP($R23,$O$7:$P$17,2,0),0)+1,U22) -> 4 | W23: =W22+1 -> 16
B24: Obligaciones Mensuales | C24: ='Entrevista Patrimonio F.'!P21+'Entrevista Patrimonio F.'!P23 -> 20000 | F24: Resultado | G24: =IF(G23>=1,"Excedido","Insuficiente") -> Excedido | R24: =R23+1 -> 17 | S24: =MAX(IFERROR(VLOOKUP($R24,$M$7:$P$17,4,0),0)+1,S23) -> 2 | T24: =MAX(IFERROR(VLOOKUP($R24,$N$7:$P$17,3,0),0)+1,T23) -> 3 | U24: =MAX(IFERROR(VLOOKUP($R24,$O$7:$P$17,2,0),0)+1,U23) -> 4 | W24: =W23+1 -> 17
B25: Obligaciones Totales | C25: =C24 -> 20000 | D25: =C25/$C$19 -> 0.18181818 | F25: Pendiente por Ahorrar | G25: =IF(G24="Insuficiente",(C26*12)-G22,0) -> 0 | R25: =R24+1 -> 18 | S25: =MAX(IFERROR(VLOOKUP($R25,$M$7:$P$17,4,0),0)+1,S24) -> 3 | T25: =MAX(IFERROR(VLOOKUP($R25,$N$7:$P$17,3,0),0)+1,T24) -> 4 | U25: =MAX(IFERROR(VLOOKUP($R25,$O$7:$P$17,2,0),0)+1,U24) -> 4 | W25: =W24+1 -> 18 | X25: =4*$X$3 -> 8800000 | Y25: =8*$X$3 -> 17600000
B26: Gastos Totales | C26: =C23+C25 -> 60000 | F26: Remanente para otros objetivos | G26: 0 | R26: =R25+1 -> 19 | S26: =MAX(IFERROR(VLOOKUP($R26,$M$7:$P$17,4,0),0)+1,S25) -> 3 | T26: =MAX(IFERROR(VLOOKUP($R26,$N$7:$P$17,3,0),0)+1,T25) -> 4 | U26: =MAX(IFERROR(VLOOKUP($R26,$O$7:$P$17,2,0),0)+1,U25) -> 4 | W26: =W25+1 -> 19
F27: Longevidad | G27: =C7+G23 -> 52.916667 | R27: =R26+1 -> 20 | S27: =MAX(IFERROR(VLOOKUP($R27,$M$7:$P$17,4,0),0)+1,S26) -> 3 | T27: =MAX(IFERROR(VLOOKUP($R27,$N$7:$P$17,3,0),0)+1,T26) -> 4 | U27: =MAX(IFERROR(VLOOKUP($R27,$O$7:$P$17,2,0),0)+1,U26) -> 4 | W27: =W26+1 -> 20
B28: Activos Financieros | R28: =R27+1 -> 21 | S28: =MAX(IFERROR(VLOOKUP($R28,$M$7:$P$17,4,0),0)+1,S27) -> 3 | T28: =MAX(IFERROR(VLOOKUP($R28,$N$7:$P$17,3,0),0)+1,T27) -> 4 | U28: =MAX(IFERROR(VLOOKUP($R28,$O$7:$P$17,2,0),0)+1,U27) -> 5 | W28: =W27+1 -> 21 | Z28: =16*$X$3 -> 35200000
B29: Saldo Débito e Inversiones Líquidas | C29: ='Entrevista Patrimonio F.'!L29 -> 200000 | F29: Output 4 (Pensión con Ahorro Financiero para retiro) | R29: =R28+1 -> 22 | S29: =MAX(IFERROR(VLOOKUP($R29,$M$7:$P$17,4,0),0)+1,S28) -> 3 | T29: =MAX(IFERROR(VLOOKUP($R29,$N$7:$P$17,3,0),0)+1,T28) -> 4 | U29: =MAX(IFERROR(VLOOKUP($R29,$O$7:$P$17,2,0),0)+1,U28) -> 5 | W29: =W28+1 -> 22
B30: Saldo otras Inversiones | C30: ='Entrevista Patrimonio F.'!L31 -> 2000000 | F30: Mensualidad Afore | G30: =PMT(1%/12,(FinRecursos-InicioDesacumulacion)*12,((C31*(1+1%/12)^((InicioDesacumulacion-EdadActual)*12))),0,1)*-1 -> 3551.5588 | R30: =R29+1 -> 23 | S30: =MAX(IFERROR(VLOOKUP($R30,$M$7:$P$17,4,0),0)+1,S29) -> 3 | T30: =MAX(IFERROR(VLOOKUP($R30,$N$7:$P$17,3,0),0)+1,T29) -> 4 | U30: =MAX(IFERROR(VLOOKUP($R30,$O$7:$P$17,2,0),0)+1,U29) -> 5 | W30: =W29+1 -> 23
B31: Saldo Afore | C31: ='Entrevista Patrimonio F.'!P38 -> 1000000 | F31: Mensualidad Pensión Voluntaria | G31: =PMT(1%/12,(FinRecursos-InicioDesacumulacion)*12,((SUM(C32:C34)*(1+1%/12)^((InicioDesacumulacion-EdadActual)*12))),0,1)*-1 -> 0 | R31: =R30+1 -> 24 | S31: =MAX(IFERROR(VLOOKUP($R31,$M$7:$P$17,4,0),0)+1,S30) -> 3 | T31: =MAX(IFERROR(VLOOKUP($R31,$N$7:$P$17,3,0),0)+1,T30) -> 5 | U31: =MAX(IFERROR(VLOOKUP($R31,$O$7:$P$17,2,0),0)+1,U30) -> 5 | W31: =W30+1 -> 24 | Y31: =16*$X$3 -> 35200000
B32: Saldo Plan Privado | C32: ='Entrevista Patrimonio F.'!P42 -> 0 | F32: Pension Estimada | G32: =C37 -> 35000 | R32: =R31+1 -> 25 | S32: =MAX(IFERROR(VLOOKUP($R32,$M$7:$P$17,4,0),0)+1,S31) -> 3 | T32: =MAX(IFERROR(VLOOKUP($R32,$N$7:$P$17,3,0),0)+1,T31) -> 5 | U32: =MAX(IFERROR(VLOOKUP($R32,$O$7:$P$17,2,0),0)+1,U31) -> 5 | W32: =W31+1 -> 25
B33: Saldo PPR | C33: ='Entrevista Patrimonio F.'!P40 -> 0 | F33: Mensualidad Actual | G33: =G30+G31+G32 -> 38551.559 | R33: =R32+1 -> 26 | S33: =MAX(IFERROR(VLOOKUP($R33,$M$7:$P$17,4,0),0)+1,S32) -> 3 | T33: =MAX(IFERROR(VLOOKUP($R33,$N$7:$P$17,3,0),0)+1,T32) -> 5 | U33: =MAX(IFERROR(VLOOKUP($R33,$O$7:$P$17,2,0),0)+1,U32) -> 6 | W33: =W32+1 -> 26 | Z33: =32*$X$3 -> 70400000
B34: Saldo en Plan de Seguros de Retiro | C34: ='Entrevista Patrimonio F.'!P44 -> 0 | F34: Grado de Avance | G34: =G33/C13 -> 0.77103118 | R34: =R33+1 -> 27 | S34: =MAX(IFERROR(VLOOKUP($R34,$M$7:$P$17,4,0),0)+1,S33) -> 4 | T34: =MAX(IFERROR(VLOOKUP($R34,$N$7:$P$17,3,0),0)+1,T33) -> 5 | U34: =MAX(IFERROR(VLOOKUP($R34,$O$7:$P$17,2,0),0)+1,U33) -> 6 | W34: =W33+1 -> 27 | X34: =8*$X$3 -> 17600000
B35: Saldo en Plan de Seguros de Acumulación | C35: ='Entrevista Patrimonio F.'!L33 -> 100000 | F35: Saldo en esquemas de retiro | G35: =SUM(C31:C34) -> 1000000 | R35: =R34+1 -> 28 | S35: =MAX(IFERROR(VLOOKUP($R35,$M$7:$P$17,4,0),0)+1,S34) -> 4 | T35: =MAX(IFERROR(VLOOKUP($R35,$N$7:$P$17,3,0),0)+1,T34) -> 5 | U35: =MAX(IFERROR(VLOOKUP($R35,$O$7:$P$17,2,0),0)+1,U34) -> 6 | W35: =W34+1 -> 28
B36: Activos Financieros Totales | C36: =SUM(C29:C35) -> 3300000 | F36: Edad en la que aplica Ley 73 | G36: =YEAR(TODAY())-1997+18 -> 47 | R36: =R35+1 -> 29 | S36: =MAX(IFERROR(VLOOKUP($R36,$M$7:$P$17,4,0),0)+1,S35) -> 4 | T36: =MAX(IFERROR(VLOOKUP($R36,$N$7:$P$17,3,0),0)+1,T35) -> 5 | U36: =MAX(IFERROR(VLOOKUP($R36,$O$7:$P$17,2,0),0)+1,U35) -> 6 | W36: =W35+1 -> 29
B37: Ley 73 | C37: ='Entrevista Patrimonio F.'!P46 -> 35000 | D37: Mensual | R37: =R36+1 -> 30 | S37: =MAX(IFERROR(VLOOKUP($R37,$M$7:$P$17,4,0),0)+1,S36) -> 4 | T37: =MAX(IFERROR(VLOOKUP($R37,$N$7:$P$17,3,0),0)+1,T36) -> 6 | U37: =MAX(IFERROR(VLOOKUP($R37,$O$7:$P$17,2,0),0)+1,U36) -> 6 | W37: =W36+1 -> 30 | Y37: =32*$X$3 -> 70400000
F38: Output 5 Integración fuentes de ingreso (Retiro) | R38: =R37+1 -> 31 | S38: =MAX(IFERROR(VLOOKUP($R38,$M$7:$P$17,4,0),0)+1,S37) -> 4 | T38: =MAX(IFERROR(VLOOKUP($R38,$N$7:$P$17,3,0),0)+1,T37) -> 6 | U38: =MAX(IFERROR(VLOOKUP($R38,$O$7:$P$17,2,0),0)+1,U37) -> 7 | W38: =W37+1 -> 31 | Z38: =64*$X$3 -> 140800000
B39: Ahorro Disponible | F39: Calidad de Vida Retiro | G39: =C13 -> 50000 | R39: =R38+1 -> 32 | S39: =MAX(IFERROR(VLOOKUP($R39,$M$7:$P$17,4,0),0)+1,S38) -> 4 | T39: =MAX(IFERROR(VLOOKUP($R39,$N$7:$P$17,3,0),0)+1,T38) -> 6 | U39: =MAX(IFERROR(VLOOKUP($R39,$O$7:$P$17,2,0),0)+1,U38) -> 7 | W39: =W38+1 -> 32
B40: Ahorro Disponible para el Retiro | C40: ='Patrimonio Financiero'!AI126 -> 0 | D40: Mensual | F40: Propiedades en Renta | G40: =C17 -> 10000 | H40: =G40/$G$39 -> 0.2 | R40: =R39+1 -> 33 | S40: =MAX(IFERROR(VLOOKUP($R40,$M$7:$P$17,4,0),0)+1,S39) -> 4 | T40: =MAX(IFERROR(VLOOKUP($R40,$N$7:$P$17,3,0),0)+1,T39) -> 6 | U40: =MAX(IFERROR(VLOOKUP($R40,$O$7:$P$17,2,0),0)+1,U39) -> 7 | W40: =W39+1 -> 33
F41: Negocio/Dividendos | G41: =C18 -> 0 | H41: =G41/$G$39 -> 0 | R41: =R40+1 -> 34 | S41: =MAX(IFERROR(VLOOKUP($R41,$M$7:$P$17,4,0),0)+1,S40) -> 4 | T41: =MAX(IFERROR(VLOOKUP($R41,$N$7:$P$17,3,0),0)+1,T40) -> 6 | U41: =MAX(IFERROR(VLOOKUP($R41,$O$7:$P$17,2,0),0)+1,U40) -> 7 | W41: =W40+1 -> 34
...

Sheet Desacumulación
D2: Inputs | G2: Resultados
B3: Tasa | D3: ='Cálculos y Supuestos Edo.Res'!C4 -> 0.01 | G3: Ahorro Inicio de Aportaciones (M) | I3: =IF(D7=0,"N/A",SUMIFS(C20:AOP20,C17:AOP17,D8,C18:AOP18,1)) -> N/A
B4: Saldos Esquemas de Pensión Actual | D4: 0 | G4: Ahorro Inicio de Jubilación | I4: =SUMIFS(C20:AOP20,C17:AOP17,D9,C18:AOP18,1)+SUMIFS(C21:AOP21,C17:AOP17,D9,C18:AOP18,1) -> 2541787.3
B5: Saldos Patrimonio Actual | D5: ='Cálculos y Supuestos Edo.Res'!G51 -> 2300000 | G5: Años de Jubilación | I5: =(D10-D9) -> 30
B6: Edad Actual | D6: =EdadActual -> 50 | G6: Meses de Jubilación | I6: =I5*12 -> 360
B7: Aportaciones (M) | D7: ='Cálculos y Supuestos Edo.Res'!C40 -> 0 | E7: Azul si aportaciones = 0 | G7: Mensualidad Deseada | I7: ='Cálculos y Supuestos Edo.Res'!G46 -> 1448.4412
B8: Edad Inicio de Aportaciones (M) | D8: =EdadActual -> 50 | E8: Azul si aportaciones = 0 | G8: Mensualidades Retiro | I8: =PMT(($D$3/12),I6,I4,0,0)*-1 -> 8175.3924 | J8: Rojo < Mensualidad Deseada | Verde > Mensualidad Deseada
B9: Edad Inicio de Retiro | D9: =InicioDesacumulacion -> 60 | E9: Max = Edad de Defunción
B10: Edad Defunción | D10: =FinRecursos -> 90 | E10: Min = Edad de Retiro | Max = 90 | RC10: 40 | ADC10: .
B14: Aportación Inicial | C14: =IF(AND(C18=1,C17=$D$6),"Aportación Inicial","-") -> - | D14: =IF(AND(D18=1,D17=$D$6),"Aportación Inicial","-") -> - | E14: =IF(AND(E18=1,E17=$D$6),"Aportación Inicial","-") -> - | F14: =IF(AND(F18=1,F17=$D$6),"Aportación Inicial","-") -> - | G14: =IF(AND(G18=1,G17=$D$6),"Aportación Inicial","-") -> - | H14: =IF(AND(H18=1,H17=$D$6),"Aportación Inicial","-") -> - | I14: =IF(AND(I18=1,I17=$D$6),"Aportación Inicial","-") -> - | J14: =IF(AND(J18=1,J17=$D$6),"Aportación Inicial","-") -> - | ... AOP14: =IF(AND(AOP18=1,AOP17=$D$6),"Aportación Inicial","-") -> -
B15: Acumulación | C15: =IF(AND(IF(C17>=$D$8,1,0),IF(C17<$D$9,1,0)),"Acumulación","-") -> - | D15: =IF(AND(IF(D17>=$D$8,1,0),IF(D17<$D$9,1,0)),"Acumulación","-") -> - | E15: =IF(AND(IF(E17>=$D$8,1,0),IF(E17<$D$9,1,0)),"Acumulación","-") -> - | F15: =IF(AND(IF(F17>=$D$8,1,0),IF(F17<$D$9,1,0)),"Acumulación","-") -> - | G15: =IF(AND(IF(G17>=$D$8,1,0),IF(G17<$D$9,1,0)),"Acumulación","-") -> - | H15: =IF(AND(IF(H17>=$D$8,1,0),IF(H17<$D$9,1,0)),"Acumulación","-") -> - | I15: =IF(AND(IF(I17>=$D$8,1,0),IF(I17<$D$9,1,0)),"Acumulación","-") -> - | J15: =IF(AND(IF(J17>=$D$8,1,0),IF(J17<$D$9,1,0)),"Acumulación","-") -> - | ... AOP15: =IF(AND(IF(AOP17>=$D$8,1,0),IF(AOP17<$D$9,1,0)),"Acumulación","-") -> -
B16: Desacumulación | C16: =IF(AND(C17>=$D$9,C17<$D$10),"Desacumulación","-") -> - | D16: =IF(AND(D17>=$D$9,D17<$D$10),"Desacumulación","-") -> - | E16: =IF(AND(E17>=$D$9,E17<$D$10),"Desacumulación","-") -> - | F16: =IF(AND(F17>=$D$9,F17<$D$10),"Desacumulación","-") -> - | G16: =IF(AND(G17>=$D$9,G17<$D$10),"Desacumulación","-") -> - | H16: =IF(AND(H17>=$D$9,H17<$D$10),"Desacumulación","-") -> - | I16: =IF(AND(I17>=$D$9,I17<$D$10),"Desacumulación","-") -> - | J16: =IF(AND(J17>=$D$9,J17<$D$10),"Desacumulación","-") -> - | ... AOP16: =IF(AND(AOP17>=$D$9,AOP17<$D$10),"Desacumulación","-") -> -
B17: Edad | C17: 1 | D17: =C17 -> 1 | E17: =D17 -> 1 | F17: =E17 -> 1 | G17: =F17 -> 1 | H17: =G17 -> 1 | I17: =H17 -> 1 | J17: =I17 -> 1 | K17: =J17 -> 1 | ... N17: =M17 -> 1 | O17: =C17+1 -> 2 | P17: =D17+1 -> 2 | Q17: =E17+1 -> 2 | R17: =F17+1 -> 2 | S17: =G17+1 -> 2 | T17: =H17+1 -> 2 | U17: =I17+1 -> 2 | V17: =J17+1 -> 2 | ... AOP17: =AOD17+1 -> 90
B18: Mes | C18: 1 | D18: =C18+1 -> 2 | E18: =D18+1 -> 3 | F18: =E18+1 -> 4 | G18: =F18+1 -> 5 | H18: =G18+1 -> 6 | I18: =H18+1 -> 7 | J18: =I18+1 -> 8 | K18: =J18+1 -> 9 | ... N18: =M18+1 -> 12 | O18: =C18 -> 1 | P18: =D18 -> 2 | Q18: =E18 -> 3 | R18: =F18 -> 4 | S18: =G18 -> 5 | T18: =H18 -> 6 | U18: =I18 -> 7 | V18: =J18 -> 8 | ... AOP18: =AOD18 -> 12
B20: Saldo Inicial | C20: 0 | D20: =C25 -> 0 | E20: =D25 -> 0 | F20: =E25 -> 0 | G20: =F25 -> 0 | H20: =G25 -> 0 | I20: =H25 -> 0 | J20: =I25 -> 0 | K20: =J25 -> 0 | ... AOP20: =AOO25 -> 2848291.2
B21: Aportación Inicial | C21: =IF(C14="Aportación Inicial",$D$5+$D$4,0) -> 0 | D21: =IF(D14="Aportación Inicial",$D$5+$D$4,0) -> 0 | E21: =IF(E14="Aportación Inicial",$D$5+$D$4,0) -> 0 | F21: =IF(F14="Aportación Inicial",$D$5+$D$4,0) -> 0 | G21: =IF(G14="Aportación Inicial",$D$5+$D$4,0) -> 0 | H21: =IF(H14="Aportación Inicial",$D$5+$D$4,0) -> 0 | I21: =IF(I14="Aportación Inicial",$D$5+$D$4,0) -> 0 | J21: =IF(J14="Aportación Inicial",$D$5+$D$4,0) -> 0 | ... AOP21: =IF(AOP14="Aportación Inicial",$D$5+$D$4,0) -> 0
B22: Aportaciones Mensuales | C22: =IF(C15="Acumulación",$D$7,0) -> 0 | D22: =IF(D15="Acumulación",$D$7,0) -> 0 | E22: =IF(E15="Acumulación",$D$7,0) -> 0 | F22: =IF(F15="Acumulación",$D$7,0) -> 0 | G22: =IF(G15="Acumulación",$D$7,0) -> 0 | H22: =IF(H15="Acumulación",$D$7,0) -> 0 | I22: =IF(I15="Acumulación",$D$7,0) -> 0 | J22: =IF(J15="Acumulación",$D$7,0) -> 0 | ... AOP22: =IF(AOP15="Acumulación",$D$7,0) -> 0
B23: Mensualidad Retiro | C23: =IF(C16="Desacumulación",$I$7,0) -> 0 | D23: =IF(D16="Desacumulación",$I$7,0) -> 0 | E23: =IF(E16="Desacumulación",$I$7,0) -> 0 | F23: =IF(F16="Desacumulación",$I$7,0) -> 0 | G23: =IF(G16="Desacumulación",$I$7,0) -> 0 | H23: =IF(H16="Desacumulación",$I$7,0) -> 0 | I23: =IF(I16="Desacumulación",$I$7,0) -> 0 | J23: =IF(J16="Desacumulación",$I$7,0) -> 0 | ... AOP23: =IF(AOP16="Desacumulación",$I$7,0) -> 0
B24: Intereses | C24: =(C20+C21-C23)*($D$3/12) -> 0 | D24: =(D20+D21-D23)*($D$3/12) -> 0 | E24: =(E20+E21-E23)*($D$3/12) -> 0 | F24: =(F20+F21-F23)*($D$3/12) -> 0 | G24: =(G20+G21-G23)*($D$3/12) -> 0 | H24: =(H20+H21-H23)*($D$3/12) -> 0 | I24: =(I20+I21-I23)*($D$3/12) -> 0 | J24: =(J20+J21-J23)*($D$3/12) -> 0 | ... AOP24: =(AOP20+AOP21-AOP23)*($D$3/12) -> 2373.576
B25: Saldo Final | C25: =IF(AND(C16="Desacumulación",D16="-"),ROUND(C20+C21+C22-C23+C24,2),C20+C21+C22-C23+C24) -> 0 | D25: =IF(AND(D16="Desacumulación",E16="-"),ROUND(D20+D21+D22-D23+D24,2),D20+D21+D22-D23+D24) -> 0 | E25: =IF(AND(E16="Desacumulación",F16="-"),ROUND(E20+E21+E22-E23+E24,2),E20+E21+E22-E23+E24) -> 0 | F25: =IF(AND(F16="Desacumulación",G16="-"),ROUND(F20+F21+F22-F23+F24,2),F20+F21+F22-F23+F24) -> 0 | G25: =IF(AND(G16="Desacumulación",H16="-"),ROUND(G20+G21+G22-G23+G24,2),G20+G21+G22-G23+G24) -> 0 | H25: =IF(AND(H16="Desacumulación",I16="-"),ROUND(H20+H21+H22-H23+H24,2),H20+H21+H22-H23+H24) -> 0 | I25: =IF(AND(I16="Desacumulación",J16="-"),ROUND(I20+I21+I22-I23+I24,2),I20+I21+I22-I23+I24) -> 0 | J25: =IF(AND(J16="Desacumulación",K16="-"),ROUND(J20+J21+J22-J23+J24,2),J20+J21+J22-J23+J24) -> 0 | ... AOP25: =IF(AND(AOP16="Desacumulación",AOQ16="-"),ROUND(AOP20+AOP21+AOP22-AOP23+AOP24,2),AOP20+AOP21+AOP22-AOP23+AOP24) -> 2850664.8
B28: Gráficas
B30: Desacumulación
C31: 12 | D31: 12 | E31: 12 | F31: 12 | G31: 12 | H31: 12 | I31: 12 | J31: 12 | K31: 12 | L31: 12 | M31: 12 | N31: 12 | O31: 12 | P31: 12 | Q31: 12 | R31: 12 | S31: 12 | T31: 12 | U31: 12 | V31: 12 | W31: 12 | X31: 12 | Y31: 12 | Z31: 12 | AA31: 12
B32: Edad | C32: =Desacumulación!D9 -> 60 | D32: =IFERROR(IF(C32+1>=Desacumulación!$D$10,"",C32+1),"") -> 61 | E32: =IFERROR(IF(D32+1>=Desacumulación!$D$10,"",D32+1),"") -> 62 | F32: =IFERROR(IF(E32+1>=Desacumulación!$D$10,"",E32+1),"") -> 63 | G32: =IFERROR(IF(F32+1>=Desacumulación!$D$10,"",F32+1),"") -> 64 | H32: =IFERROR(IF(G32+1>=Desacumulación!$D$10,"",G32+1),"") -> 65 | I32: =IFERROR(IF(H32+1>=Desacumulación!$D$10,"",H32+1),"") -> 66 | J32: =IFERROR(IF(I32+1>=Desacumulación!$D$10,"",I32+1),"") -> 67 | K32: =IFERROR(IF(J32+1>=Desacumulación!$D$10,"",J32+1),"") -> 68 | ... AA32: =IFERROR(IF(Z32+1>=Desacumulación!$D$10,"",Z32+1),"") -> 84
B33: Saldo Inicial | C33: =Desacumulación!I4 -> 2541787.3 | D33: =IF(D32="","",C34) -> 2549846.2 | E33: =IF(E32="","",D34) -> 2557986.1 | F33: =IF(F32="","",E34) -> 2566207.8 | G33: =IF(G32="","",F34) -> 2574512.1 | H33: =IF(H32="","",G34) -> 2582899.9 | I33: =IF(I32="","",H34) -> 2591371.8 | J33: =IF(J32="","",I34) -> 2599928.9 | K33: =IF(K32="","",J34) -> 2608572 | ... AA33: =IF(AA32="","",Z34) -> 2759283.9
B34: Saldo Final | C34: =IF(C32="","",SUMIFS(Desacumulación!$C$25:$AOP$25,Desacumulación!$C$17:$AOP$17,C32,Desacumulación!$C$18:$AOP$18,C31)) -> 2549846.2 | D34: =IF(D32="","",SUMIFS(Desacumulación!$C$25:$AOP$25,Desacumulación!$C$17:$AOP$17,D32,Desacumulación!$C$18:$AOP$18,D31)) -> 2557986.1 | E34: =IF(E32="","",SUMIFS(Desacumulación!$C$25:$AOP$25,Desacumulación!$C$17:$AOP$17,E32,Desacumulación!$C$18:$AOP$18,E31)) -> 2566207.8 | F34: =IF(F32="","",SUMIFS(Desacumulación!$C$25:$AOP$25,Desacumulación!$C$17:$AOP$17,F32,Desacumulación!$C$18:$AOP$18,F31)) -> 2574512.1 | G34: =IF(G32="","",SUMIFS(Desacumulación!$C$25:$AOP$25,Desacumulación!$C$17:$AOP$17,G32,Desacumulación!$C$18:$AOP$18,G31)) -> 2582899.9 | H34: =IF(H32="","",SUMIFS(Desacumulación!$C$25:$AOP$25,Desacumulación!$C$17:$AOP$17,H32,Desacumulación!$C$18:$AOP$18,H31)) -> 2591371.8 | I34: =IF(I32="","",SUMIFS(Desacumulación!$C$25:$AOP$25,Desacumulación!$C$17:$AOP$17,I32,Desacumulación!$C$18:$AOP$18,I31)) -> 2599928.9 | J34: =IF(J32="","",SUMIFS(Desacumulación!$C$25:$AOP$25,Desacumulación!$C$17:$AOP$17,J32,Desacumulación!$C$18:$AOP$18,J31)) -> 2608572 | ... AA34: =IF(AA32="","",SUMIFS(Desacumulación!$C$25:$AOP$25,Desacumulación!$C$17:$AOP$17,AA32,Desacumulación!$C$18:$AOP$18,AA31)) -> 2769527.9

Sheet Objetivos
C2: Inputs | F2: Resultados
B3: Tasa | C3: ='Cálculos y Supuestos Edo.Res'!C4 -> 0.01 | F3: Ahorro Inicio de Aportaciones (M) | H3: =IF(C7=0,"N/A",SUMIFS(D20:AOQ20,D15:AOQ15,C8,D16:AOQ16,1)) -> 0
B4: Aportación Inicial | C4: ='Patrimonio Financiero'!AP200 -> 400000 | F4: Ahorro Inicio de Jubilación | H4: =SUMIFS(D20:AOQ20,D15:AOQ15,C9,D16:AOQ16,1)+SUMIFS(D21:AOQ21,D15:AOQ15,C9,D16:AOQ16,1) -> 1774127.4
B5: Edad de Aportación Inicial | C5: =EdadActual -> 50 | F5: Años de Jubilación | H5: =(C10-C9) -> 30
B6: Aportaciones (A) | C6: ='Patrimonio Financiero'!AP196 -> 150000 | F6: Meses de Jubilación | H6: =H5*12 -> 360
B7: Aportaciones (M) | C7: ='Patrimonio Financiero'!AE196 -> 15000 | D7: Azul si aportaciones = 0 | F7: Mensualidad Deseada | H7: ='Cálculos y Supuestos Edo.Res'!G46 -> 1448.4412
B8: Edad Inicio de Aportaciones (M) | C8: =EdadActual -> 50 | D8: Azul si aportaciones = 0 | F8: Mensualidades Retiro | H8: =PMT(($C$3/12),H6,H4,0,1)*-1 -> 5701.5436 | I8: Rojo < Mensualidad Deseada | Verde > Mensualidad Deseada
B9: Edad Inicio de Retiro | C9: =InicioDesacumulacion -> 60 | D9: Max = Edad de Defunción
B10: Edad Defunción | C10: =FinRecursos -> 90 | D10: Min = Edad de Retiro | Max = 90 | F10: Ahorro Fecha de Defunción | H10: =AOE25 -> 2394522.3
RD11: 40 | ADD11: .
B12: Aportación Inicial | D12: =IF(AND(D16=1,D15=$C$5),"Aportación Inicial","-") -> - | E12: =IF(AND(E16=1,E15=$C$5),"Aportación Inicial","-") -> - | F12: =IF(AND(F16=1,F15=$C$5),"Aportación Inicial","-") -> - | G12: =IF(AND(G16=1,G15=$C$5),"Aportación Inicial","-") -> - | H12: =IF(AND(H16=1,H15=$C$5),"Aportación Inicial","-") -> - | I12: =IF(AND(I16=1,I15=$C$5),"Aportación Inicial","-") -> - | J12: =IF(AND(J16=1,J15=$C$5),"Aportación Inicial","-") -> - | K12: =IF(AND(K16=1,K15=$C$5),"Aportación Inicial","-") -> - | ... AOQ12: =IF(AND(AOQ16=1,AOQ15=$C$5),"Aportación Inicial","-") -> -
B13: Acumulación | D13: =IF(AND(IF(D15>=$C$8,1,0),IF(D15<$C$9,1,0)),"Acumulación","-") -> - | E13: =IF(AND(IF(E15>=$C$8,1,0),IF(E15<$C$9,1,0)),"Acumulación","-") -> - | F13: =IF(AND(IF(F15>=$C$8,1,0),IF(F15<$C$9,1,0)),"Acumulación","-") -> - | G13: =IF(AND(IF(G15>=$C$8,1,0),IF(G15<$C$9,1,0)),"Acumulación","-") -> - | H13: =IF(AND(IF(H15>=$C$8,1,0),IF(H15<$C$9,1,0)),"Acumulación","-") -> - | I13: =IF(AND(IF(I15>=$C$8,1,0),IF(I15<$C$9,1,0)),"Acumulación","-") -> - | J13: =IF(AND(IF(J15>=$C$8,1,0),IF(J15<$C$9,1,0)),"Acumulación","-") -> - | K13: =IF(AND(IF(K15>=$C$8,1,0),IF(K15<$C$9,1,0)),"Acumulación","-") -> - | ... AOQ13: =IF(AND(IF(AOQ15>=$C$8,1,0),IF(AOQ15<$C$9,1,0)),"Acumulación","-") -> -
B14: Desacumulación | D14: =IF(AND(D15>=$C$9,D15<$C$10),"Desacumulación","-") -> - | E14: =IF(AND(E15>=$C$9,E15<$C$10),"Desacumulación","-") -> - | F14: =IF(AND(F15>=$C$9,F15<$C$10),"Desacumulación","-") -> - | G14: =IF(AND(G15>=$C$9,G15<$C$10),"Desacumulación","-") -> - | H14: =IF(AND(H15>=$C$9,H15<$C$10),"Desacumulación","-") -> - | I14: =IF(AND(I15>=$C$9,I15<$C$10),"Desacumulación","-") -> - | J14: =IF(AND(J15>=$C$9,J15<$C$10),"Desacumulación","-") -> - | K14: =IF(AND(K15>=$C$9,K15<$C$10),"Desacumulación","-") -> - | ... AOQ14: =IF(AND(AOQ15>=$C$9,AOQ15<$C$10),"Desacumulación","-") -> -
B15: Edad | D15: 1 | E15: =D15 -> 1 | F15: =E15 -> 1 | G15: =F15 -> 1 | H15: =G15 -> 1 | I15: =H15 -> 1 | J15: =I15 -> 1 | K15: =J15 -> 1 | L15: =K15 -> 1 | ... O15: =N15 -> 1 | P15: =D15+1 -> 2 | Q15: =E15+1 -> 2 | R15: =F15+1 -> 2 | S15: =G15+1 -> 2 | T15: =H15+1 -> 2 | U15: =I15+1 -> 2 | V15: =J15+1 -> 2 | W15: =K15+1 -> 2 | ... AOQ15: =AOE15+1 -> 90
B16: Mes | D16: 1 | E16: =D16+1 -> 2 | F16: =E16+1 -> 3 | G16: =F16+1 -> 4 | H16: =G16+1 -> 5 | I16: =H16+1 -> 6 | J16: =I16+1 -> 7 | K16: =J16+1 -> 8 | L16: =K16+1 -> 9 | ... O16: =N16+1 -> 12 | P16: =D16 -> 1 | Q16: =E16 -> 2 | R16: =F16 -> 3 | S16: =G16 -> 4 | T16: =H16 -> 5 | U16: =I16 -> 6 | V16: =J16 -> 7 | W16: =K16 -> 8 | ... AOQ16: =AOE16 -> 12
B17: Contador | D17: 1 | E17: =D17+1 -> 2 | F17: =E17+1 -> 3 | G17: =F17+1 -> 4 | H17: =G17+1 -> 5 | I17: =H17+1 -> 6 | J17: =I17+1 -> 7 | K17: =J17+1 -> 8 | L17: =K17+1 -> 9 | ... AOQ17: =AOP17+1 -> 1080
B18: Objetivos | D18: =IF(D15>=$C$5,1,0) -> 0 | E18: =IF(E15>=$C$5,1,0) -> 0 | F18: =IF(F15>=$C$5,1,0) -> 0 | G18: =IF(G15>=$C$5,1,0) -> 0 | H18: =IF(H15>=$C$5,1,0) -> 0 | I18: =IF(I15>=$C$5,1,0) -> 0 | J18: =IF(J15>=$C$5,1,0) -> 0 | K18: =IF(K15>=$C$5,1,0) -> 0 | ... AOQ18: =IF(AOQ15>=$C$5,1,0) -> 1
B20: Saldo Inicial | D20: 0 | E20: =D25 -> 0 | F20: =E25 -> 0 | G20: =F25 -> 0 | H20: =G25 -> 0 | I20: =H25 -> 0 | J20: =I25 -> 0 | K20: =J25 -> 0 | L20: =K25 -> 0 | ... AOQ20: =AOP25 -> 2416563.8
B21: Aportación Inicial | D21: =IF(D12="Aportación Inicial",$C$4,0) -> 0 | E21: =IF(E12="Aportación Inicial",$C$4,0) -> 0 | F21: =IF(F12="Aportación Inicial",$C$4,0) -> 0 | G21: =IF(G12="Aportación Inicial",$C$4,0) -> 0 | H21: =IF(H12="Aportación Inicial",$C$4,0) -> 0 | I21: =IF(I12="Aportación Inicial",$C$4,0) -> 0 | J21: =IF(J12="Aportación Inicial",$C$4,0) -> 0 | K21: =IF(K12="Aportación Inicial",$C$4,0) -> 0 | ... AOQ21: =IF(AOQ12="Aportación Inicial",$C$4,0) -> 0
B22: Aportaciones Mensuales | D22: =IF(D13="Acumulación",$C$7,0)++IF(AND(D13="Acumulación",D16=1),$C$6,0) -> 0 | E22: =IF(E13="Acumulación",$C$7,0)++IF(AND(E13="Acumulación",E16=1),$C$6,0) -> 0 | F22: =IF(F13="Acumulación",$C$7,0)++IF(AND(F13="Acumulación",F16=1),$C$6,0) -> 0 | G22: =IF(G13="Acumulación",$C$7,0)++IF(AND(G13="Acumulación",G16=1),$C$6,0) -> 0 | H22: =IF(H13="Acumulación",$C$7,0)++IF(AND(H13="Acumulación",H16=1),$C$6,0) -> 0 | I22: =IF(I13="Acumulación",$C$7,0)++IF(AND(I13="Acumulación",I16=1),$C$6,0) -> 0 | J22: =IF(J13="Acumulación",$C$7,0)++IF(AND(J13="Acumulación",J16=1),$C$6,0) -> 0 | K22: =IF(K13="Acumulación",$C$7,0)++IF(AND(K13="Acumulación",K16=1),$C$6,0) -> 0 | ... AOQ22: =IF(AOQ13="Acumulación",$C$7,0)++IF(AND(AOQ13="Acumulación",AOQ16=1),$C$6,0) -> 0
B23: Retiros de Objetivos | D23: =D28+D35+D42+D49+D56 -> 0 | E23: =E28+E35+E42+E49+E56 -> 0 | F23: =F28+F35+F42+F49+F56 -> 0 | G23: =G28+G35+G42+G49+G56 -> 0 | H23: =H28+H35+H42+H49+H56 -> 0 | I23: =I28+I35+I42+I49+I56 -> 0 | J23: =J28+J35+J42+J49+J56 -> 0 | K23: =K28+K35+K42+K49+K56 -> 0 | ... AOQ23: =AOQ28+AOQ35+AOQ42+AOQ49+AOQ56 -> 0
B24: Intereses | D24: =(D20+D21+D22-D23)*($C$3/12) -> 0 | E24: =(E20+E21+E22-E23)*($C$3/12) -> 0 | F24: =(F20+F21+F22-F23)*($C$3/12) -> 0 | G24: =(G20+G21+G22-G23)*($C$3/12) -> 0 | H24: =(H20+H21+H22-H23)*($C$3/12) -> 0 | I24: =(I20+I21+I22-I23)*($C$3/12) -> 0 | J24: =(J20+J21+J22-J23)*($C$3/12) -> 0 | K24: =(K20+K21+K22-K23)*($C$3/12) -> 0 | ... AOQ24: =(AOQ20+AOQ21+AOQ22-AOQ23)*($C$3/12) -> 2013.8032
B25: Saldo Final | D25: =IF(AND(D14="Desacumulación",E14="-"),ROUND(D20+D21+D22-D23+D24,2),D20+D21+D22-D23+D24) -> 0 | E25: =IF(AND(E14="Desacumulación",F14="-"),ROUND(E20+E21+E22-E23+E24,2),E20+E21+E22-E23+E24) -> 0 | F25: =IF(AND(F14="Desacumulación",G14="-"),ROUND(F20+F21+F22-F23+F24,2),F20+F21+F22-F23+F24) -> 0 | G25: =IF(AND(G14="Desacumulación",H14="-"),ROUND(G20+G21+G22-G23+G24,2),G20+G21+G22-G23+G24) -> 0 | H25: =IF(AND(H14="Desacumulación",I14="-"),ROUND(H20+H21+H22-H23+H24,2),H20+H21+H22-H23+H24) -> 0 | I25: =IF(AND(I14="Desacumulación",J14="-"),ROUND(I20+I21+I22-I23+I24,2),I20+I21+I22-I23+I24) -> 0 | J25: =IF(AND(J14="Desacumulación",K14="-"),ROUND(J20+J21+J22-J23+J24,2),J20+J21+J22-J23+J24) -> 0 | K25: =IF(AND(K14="Desacumulación",L14="-"),ROUND(K20+K21+K22-K23+K24,2),K20+K21+K22-K23+K24) -> 0 | ... AOQ25: =IF(AND(AOQ14="Desacumulación",AOR14="-"),ROUND(AOQ20+AOQ21+AOQ22-AOQ23+AOQ24,2),AOQ20+AOQ21+AOQ22-AOQ23+AOQ24) -> 2418577.6
RD26: Acumulacion | RE26: Acumulacion | RF26: Acumulacion | RG26: Acumulacion | RH26: Acumulacion | RI26: Acumulacion | RJ26: Acumulacion | RK26: Acumulacion | RL26: Acumulacion | RM26: Acumulacion | RN26: Acumulacion | RO26: Acumulacion | RP26: Acumulacion | RQ26: Acumulacion | RR26: Acumulacion | RS26: Acumulacion | RT26: Acumulacion | RU26: Acumulacion | RV26: Acumulacion | RW26: Acumulacion | RX26: Acumulacion | RY26: Acumulacion | RZ26: Acumulacion | SA26: Acumulacion | SB26: Acumulacion | SC26: Acumulacion | SD26: Acumulacion | SE26: Acumulacion | SF26: Acumulacion | SG26: Acumulacion | SH26: Acumulacion | SI26: Acumulacion | SJ26: Acumulacion | SK26: Acumulacion | SL26: Acumulacion | SM26: Acumulacion | SN26: Acumulacion | SO26: Acumulacion | SP26: Acumulacion | SQ26: Acumulacion | SR26: Acumulacion | SS26: Acumulacion | ST26: Acumulacion | SU26: Acumulacion | SV26: Acumulacion | SW26: Acumulacion | SX26: Acumulacion | SY26: Acumulacion | SZ26: Acumulacion | TA26: Acumulacion | TB26: Acumulacion | TC26: Acumulacion | TD26: Acumulacion | TE26: Acumulacion | TF26: Acumulacion | TG26: Acumulacion | TH26: Acumulacion | TI26: Acumulacion | TJ26: Acumulacion | TK26: Acumulacion | TL26: Acumulacion | TM26: Acumulacion | TN26: Acumulacion | TO26: Acumulacion | TP26: Acumulacion | TQ26: Acumulacion | TR26: Acumulacion | TS26: Acumulacion | TT26: Acumulacion | TU26: Acumulacion | TV26: Acumulacion | TW26: Acumulacion | TX26: Acumulacion | TY26: Acumulacion | TZ26: Acumulacion | UA26: Acumulacion | UB26: Acumulacion | UC26: Acumulacion | UD26: Acumulacion | UE26: Acumulacion | UF26: Acumulacion | UG26: Acumulacion | UH26: Acumulacion | UI26: Acumulacion | UJ26: Acumulacion | UK26: Acumulacion | UL26: Acumulacion | UM26: Acumulacion | UN26: Acumulacion | UO26: Acumulacion | UP26: Acumulacion | UQ26: Acumulacion | UR26: Acumulacion | US26: Acumulacion | UT26: Acumulacion | UU26: Acumulacion | UV26: Acumulacion | UW26: Acumulacion | UX26: Acumulacion | UY26: Acumulacion | UZ26: Acumulacion | VA26: Acumulacion | VB26: Acumulacion | VC26: Acumulacion | VD26: Acumulacion | VE26: Acumulacion | VF26: Acumulacion | VG26: Acumulacion | VH26: Acumulacion | VI26: Acumulacion | VJ26: Acumulacion | VK26: Acumulacion | VL26: Acumulacion | VM26: Acumulacion | VN26: Acumulacion | VO26: Acumulacion | VP26: Acumulacion | VQ26: Acumulacion | VR26: Acumulacion | VS26: Acumulacion | VT26: Acumulacion | VU26: Acumulacion | VV26: Acumulacion | VW26: Acumulacion | VX26: Acumulacion | VY26: Acumulacion | VZ26: Acumulacion | WA26: Acumulacion | WB26: Acumulacion | WC26: Acumulacion | WD26: Acumulacion | WE26: Acumulacion | WF26: Acumulacion | WG26: Acumulacion | WH26: Acumulacion | WI26: Acumulacion | WJ26: Acumulacion | WK26: Acumulacion | WL26: Acumulacion | WM26: Acumulacion | WN26: Acumulacion | WO26: Acumulacion | WP26: Acumulacion | WQ26: Acumulacion | WR26: Acumulacion | WS26: Acumulacion | WT26: Acumulacion | WU26: Acumulacion | WV26: Acumulacion | WW26: Acumulacion | WX26: Acumulacion | WY26: Acumulacion | WZ26: Acumulacion | XA26: Acumulacion | XB26: Acumulacion | XC26: Acumulacion | XD26: Acumulacion | XE26: Acumulacion | XF26: Acumulacion | XG26: Acumulacion | XH26: Acumulacion | XI26: Acumulacion | XJ26: Acumulacion | XK26: Acumulacion | XL26: Acumulacion | XM26: Acumulacion | XN26: Acumulacion | XO26: Acumulacion | XP26: Acumulacion | XQ26: Acumulacion | XR26: Acumulacion | XS26: Acumulacion | XT26: Acumulacion | XU26: Acumulacion | XV26: Acumulacion | XW26: Acumulacion | XX26: Acumulacion | XY26: Acumulacion | XZ26: Acumulacion | YA26: Acumulacion | YB26: Acumulacion | YC26: Acumulacion | YD26: Acumulacion | YE26: Acumulacion | YF26: Acumulacion | YG26: Acumulacion | YH26: Acumulacion | YI26: Acumulacion | YJ26: Acumulacion | YK26: Acumulacion | YL26: Acumulacion | YM26: Acumulacion | YN26: Acumulacion | YO26: Acumulacion | YP26: Acumulacion | YQ26: Acumulacion | YR26: Acumulacion | YS26: Acumulacion | YT26: Acumulacion | YU26: Acumulacion | YV26: Acumulacion | YW26: Acumulacion | YX26: Acumulacion | YY26: Acumulacion | YZ26: Acumulacion | ZA26: Acumulacion | ZB26: Acumulacion | ZC26: Acumulacion | ZD26: Acumulacion | ZE26: Acumulacion | ZF26: Acumulacion | ZG26: Acumulacion | ZH26: Acumulacion | ZI26: Acumulacion | ZJ26: Acumulacion | ZK26: Acumulacion | ZL26: Acumulacion | ZM26: Acumulacion | ZN26: Acumulacion | ZO26: Acumulacion | ZP26: Acumulacion | ZQ26: Acumulacion | ZR26: Acumulacion | ZS26: Acumulacion | ZT26: Acumulacion | ZU26: Acumulacion | ZV26: Acumulacion | ZW26: Acumulacion | ZX26: Acumulacion | ZY26: Acumulacion | ZZ26: Acumulacion | AAA26: Acumulacion | AAB26: Acumulacion | AAC26: Acumulacion | AAD26: Acumulacion | AAE26: Acumulacion | AAF26: Acumulacion | AAG26: Acumulacion | AAH26: Acumulacion | AAI26: Acumulacion | AAJ26: Acumulacion | AAK26: Acumulacion | AAL26: Acumulacion | AAM26: Acumulacion | AAN26: Acumulacion | AAO26: Acumulacion | AAP26: Acumulacion | AAQ26: Acumulacion | AAR26: Acumulacion | AAS26: Acumulacion | AAT26: Acumulacion | AAU26: Acumulacion | AAV26: Acumulacion | AAW26: Acumulacion | AAX26: Acumulacion | AAY26: Acumulacion | AAZ26: Acumulacion | ABA26: Acumulacion | ABB26: Acumulacion | ABC26: Acumulacion | ABD26: Acumulacion | ABE26: Acumulacion | ABF26: Acumulacion | ABG26: Acumulacion | ABH26: Acumulacion | ABI26: Acumulacion | ABJ26: Acumulacion | ABK26: Acumulacion | ABL26: Acumulacion | ABM26: Acumulacion | ABN26: Acumulacion | ABO26: Acumulacion | ABP26: Acumulacion | ABQ26: Acumulacion | ABR26: Acumulacion | ABS26: Acumulacion | ABT26: Acumulacion | ABU26: Acumulacion | ABV26: Acumulacion | ABW26: Acumulacion | ABX26: Acumulacion | ABY26: Acumulacion | ABZ26: Acumulacion | ACA26: Acumulacion | ACB26: Acumulacion | ACC26: Acumulacion | ACD26: Acumulacion | ACE26: Acumulacion | ACF26: Acumulacion | ACG26: Acumulacion | ACH26: Acumulacion | ACI26: Acumulacion | ACJ26: Acumulacion | ACK26: Acumulacion | ACL26: Acumulacion | ACM26: Acumulacion | ACN26: Acumulacion | ACO26: Acumulacion | ACP26: Acumulacion | ACQ26: Acumulacion
B27: ='Patrimonio Financiero'!BH200 -> Objetivo 1 | C27: ='Patrimonio Financiero'!CB200 -> 1000000 | D27: =$C27 -> 1000000 | E27: =$C27 -> 1000000 | F27: =$C27 -> 1000000 | G27: =$C27 -> 1000000 | H27: =$C27 -> 1000000 | I27: =$C27 -> 1000000 | J27: =$C27 -> 1000000 | K27: =$C27 -> 1000000 | ... AOQ27: =$C27 -> 1000000
B28: Retiro | C28: =SUM(D28:AOQ28) -> 1000000 | D28: 0 | E28: =IF(SUM($D28:D28)>0,0,IF(D$25>D27,D27,0)) -> 0 | F28: =IF(SUM($D28:E28)>0,0,IF(E$25>E27,E27,0)) -> 0 | G28: =IF(SUM($D28:F28)>0,0,IF(F$25>F27,F27,0)) -> 0 | H28: =IF(SUM($D28:G28)>0,0,IF(G$25>G27,G27,0)) -> 0 | I28: =IF(SUM($D28:H28)>0,0,IF(H$25>H27,H27,0)) -> 0 | J28: =IF(SUM($D28:I28)>0,0,IF(I$25>I27,I27,0)) -> 0 | K28: =IF(SUM($D28:J28)>0,0,IF(J$25>J27,J27,0)) -> 0 | L28: =IF(SUM($D28:K28)>0,0,IF(K$25>K27,K27,0)) -> 0 | ... AOQ28: =IF(SUM($D28:AOP28)>0,0,IF(AOP$25>AOP27,AOP27,0)) -> 0
B29: Periodo | C29: =SUM(D29:AOQ29) -> 609 | D29: =IF(D28>0,D$17,0) -> 0 | E29: =IF(E28>0,E$17,0) -> 0 | F29: =IF(F28>0,F$17,0) -> 0 | G29: =IF(G28>0,G$17,0) -> 0 | H29: =IF(H28>0,H$17,0) -> 0 | I29: =IF(I28>0,I$17,0) -> 0 | J29: =IF(J28>0,J$17,0) -> 0 | K29: =IF(K28>0,K$17,0) -> 0 | ... AOQ29: =IF(AOQ28>0,AOQ$17,0) -> 0
B30: Numero de periodos | C30: =SUM(D30:AOQ30) -> 20 | D30: 0 | E30: =IF(E28>0,SUM($D$18:D18),0) -> 0 | F30: =IF(F28>0,SUM($D$18:E18),0) -> 0 | G30: =IF(G28>0,SUM($D$18:F18),0) -> 0 | H30: =IF(H28>0,SUM($D$18:G18),0) -> 0 | I30: =IF(I28>0,SUM($D$18:H18),0) -> 0 | J30: =IF(J28>0,SUM($D$18:I18),0) -> 0 | K30: =IF(K28>0,SUM($D$18:J18),0) -> 0 | L30: =IF(L28>0,SUM($D$18:K18),0) -> 0 | ... AOQ30: =IF(AOQ28>0,SUM($D$18:AOP18),0) -> 0
B31: Plazo | C31: =IFERROR(MAX(IF(MAX(C30,0)=0,"Saldo Insuficiente",MAX(C30,0)),0),"Saldo Insuficiente") -> 20
B33: ='Patrimonio Financiero'!BH202 -> Objetivo 2 | C33: ='Patrimonio Financiero'!CB202 -> 900000 | D33: =$C33 -> 900000 | E33: =$C33 -> 900000 | F33: =$C33 -> 900000 | G33: =$C33 -> 900000 | H33: =$C33 -> 900000 | I33: =$C33 -> 900000 | J33: =$C33 -> 900000 | K33: =$C33 -> 900000 | ... AOQ33: =$C33 -> 900000
B34: Condición | D34: 0 | E34: =IF(E28>0,D25-E28,0) -> 0 | F34: =IF(F28>0,E25-F28,0) -> 0 | G34: =IF(G28>0,F25-G28,0) -> 0 | H34: =IF(H28>0,G25-H28,0) -> 0 | I34: =IF(I28>0,H25-I28,0) -> 0 | J34: =IF(J28>0,I25-J28,0) -> 0 | K34: =IF(K28>0,J25-K28,0) -> 0 | L34: =IF(L28>0,K25-L28,0) -> 0 | ... AOQ34: =IF(AOQ28>0,AOP25-AOQ28,0) -> 0
B35: Retiro | C35: =SUM(D35:AOQ35) -> 900000 | D35: 0 | E35: =IF(SUM($D$28:D28)=0,0,IF(IF(E34>0,E34-(IF(SUM($D35:D35)>0,0,IF(D$25>D33,D33,0))),0)<0,0,(IF(SUM($D35:D35)>0,0,IF(D$25>D33,D33,0))))) -> 0 | F35: =IF(SUM($D$28:E28)=0,0,IF(IF(F34>0,F34-(IF(SUM($D35:E35)>0,0,IF(E$25>E33,E33,0))),0)<0,0,(IF(SUM($D35:E35)>0,0,IF(E$25>E33,E33,0))))) -> 0 | G35: =IF(SUM($D$28:F28)=0,0,IF(IF(G34>0,G34-(IF(SUM($D35:F35)>0,0,IF(F$25>F33,F33,0))),0)<0,0,(IF(SUM($D35:F35)>0,0,IF(F$25>F33,F33,0))))) -> 0 | H35: =IF(SUM($D$28:G28)=0,0,IF(IF(H34>0,H34-(IF(SUM($D35:G35)>0,0,IF(G$25>G33,G33,0))),0)<0,0,(IF(SUM($D35:G35)>0,0,IF(G$25>G33,G33,0))))) -> 0 | I35: =IF(SUM($D$28:H28)=0,0,IF(IF(I34>0,I34-(IF(SUM($D35:H35)>0,0,IF(H$25>H33,H33,0))),0)<0,0,(IF(SUM($D35:H35)>0,0,IF(H$25>H33,H33,0))))) -> 0 | J35: =IF(SUM($D$28:I28)=0,0,IF(IF(J34>0,J34-(IF(SUM($D35:I35)>0,0,IF(I$25>I33,I33,0))),0)<0,0,(IF(SUM($D35:I35)>0,0,IF(I$25>I33,I33,0))))) -> 0 | K35: =IF(SUM($D$28:J28)=0,0,IF(IF(K34>0,K34-(IF(SUM($D35:J35)>0,0,IF(J$25>J33,J33,0))),0)<0,0,(IF(SUM($D35:J35)>0,0,IF(J$25>J33,J33,0))))) -> 0 | L35: =IF(SUM($D$28:K28)=0,0,IF(IF(L34>0,L34-(IF(SUM($D35:K35)>0,0,IF(K$25>K33,K33,0))),0)<0,0,(IF(SUM($D35:K35)>0,0,IF(K$25>K33,K33,0))))) -> 0 | ... AOQ35: =IF(SUM($D$28:AOP28)=0,0,IF(IF(AOQ34>0,AOQ34-(IF(SUM($D35:AOP35)>0,0,IF(AOP$25>AOP33,AOP33,0))),0)<0,0,(IF(SUM($D35:AOP35)>0,0,IF(AOP$25>AOP33,AOP33,0))))) -> 0
B36: Periodo | C36: =SUM(D36:AOQ36) -> 638 | D36: =IF(D35>0,D$17,0) -> 0 | E36: =IF(E35>0,E$17,0) -> 0 | F36: =IF(F35>0,F$17,0) -> 0 | G36: =IF(G35>0,G$17,0) -> 0 | H36: =IF(H35>0,H$17,0) -> 0 | I36: =IF(I35>0,I$17,0) -> 0 | J36: =IF(J35>0,J$17,0) -> 0 | K36: =IF(K35>0,K$17,0) -> 0 | ... AOQ36: =IF(AOQ35>0,AOQ$17,0) -> 0
B37: Numero de periodos | C37: =SUM(D37:AOQ37) -> 49 | D37: 0 | E37: =IF(E35>0,SUM($D$18:D18),0) -> 0 | F37: =IF(F35>0,SUM($D$18:E18),0) -> 0 | G37: =IF(G35>0,SUM($D$18:F18),0) -> 0 | H37: =IF(H35>0,SUM($D$18:G18),0) -> 0 | I37: =IF(I35>0,SUM($D$18:H18),0) -> 0 | J37: =IF(J35>0,SUM($D$18:I18),0) -> 0 | K37: =IF(K35>0,SUM($D$18:J18),0) -> 0 | L37: =IF(L35>0,SUM($D$18:K18),0) -> 0 | ... AOQ37: =IF(AOQ35>0,SUM($D$18:AOP18),0) -> 0
B38: Plazo | C38: =IFERROR(MAX(IF(AND(MAX(IF(C36=C29,C37,C37-C30),0)=0,C33>0),"Saldo Insuficiente",IF(C36=C29,C37,C37-C30)),0),"Saldo Insuficiente") -> 29
B40: ='Patrimonio Financiero'!BH204 -> Objetivo 3 | C40: ='Patrimonio Financiero'!CB204 -> 100000 | D40: =$C40 -> 100000 | E40: =$C40 -> 100000 | F40: =$C40 -> 100000 | G40: =$C40 -> 100000 | H40: =$C40 -> 100000 | I40: =$C40 -> 100000 | J40: =$C40 -> 100000 | K40: =$C40 -> 100000 | ... AOQ40: =$C40 -> 100000
B41: Condición | D41: =IF(D28+D35>0,C25-D28-D35,0) -> 0 | E41: =IF(E28+E35>0,D25-E28-E35,0) -> 0 | F41: =IF(F28+F35>0,E25-F28-F35,0) -> 0 | G41: =IF(G28+G35>0,F25-G28-G35,0) -> 0 | H41: =IF(H28+H35>0,G25-H28-H35,0) -> 0 | I41: =IF(I28+I35>0,H25-I28-I35,0) -> 0 | J41: =IF(J28+J35>0,I25-J28-J35,0) -> 0 | K41: =IF(K28+K35>0,J25-K28-K35,0) -> 0 | ... AOQ41: =IF(AOQ28+AOQ35>0,AOP25-AOQ28-AOQ35,0) -> 0
B42: Retiro | C42: =SUM(D42:AOQ42) -> 100000 | D42: 0 | E42: =IF(SUM($D$35:D35)=0,0,IF(IF(E41>0,E41-(IF(SUM($D42:D42)>0,0,IF(D$25>D40,D40,0))),0)<0,0,(IF(SUM($D42:D42)>0,0,IF(D$25>D40,D40,0))))) -> 0 | F42: =IF(SUM($D$35:E35)=0,0,IF(IF(F41>0,F41-(IF(SUM($D42:E42)>0,0,IF(E$25>E40,E40,0))),0)<0,0,(IF(SUM($D42:E42)>0,0,IF(E$25>E40,E40,0))))) -> 0 | G42: =IF(SUM($D$35:F35)=0,0,IF(IF(G41>0,G41-(IF(SUM($D42:F42)>0,0,IF(F$25>F40,F40,0))),0)<0,0,(IF(SUM($D42:F42)>0,0,IF(F$25>F40,F40,0))))) -> 0 | H42: =IF(SUM($D$35:G35)=0,0,IF(IF(H41>0,H41-(IF(SUM($D42:G42)>0,0,IF(G$25>G40,G40,0))),0)<0,0,(IF(SUM($D42:G42)>0,0,IF(G$25>G40,G40,0))))) -> 0 | I42: =IF(SUM($D$35:H35)=0,0,IF(IF(I41>0,I41-(IF(SUM($D42:H42)>0,0,IF(H$25>H40,H40,0))),0)<0,0,(IF(SUM($D42:H42)>0,0,IF(H$25>H40,H40,0))))) -> 0 | J42: =IF(SUM($D$35:I35)=0,0,IF(IF(J41>0,J41-(IF(SUM($D42:I42)>0,0,IF(I$25>I40,I40,0))),0)<0,0,(IF(SUM($D42:I42)>0,0,IF(I$25>I40,I40,0))))) -> 0 | K42: =IF(SUM($D$35:J35)=0,0,IF(IF(K41>0,K41-(IF(SUM($D42:J42)>0,0,IF(J$25>J40,J40,0))),0)<0,0,(IF(SUM($D42:J42)>0,0,IF(J$25>J40,J40,0))))) -> 0 | L42: =IF(SUM($D$35:K35)=0,0,IF(IF(L41>0,L41-(IF(SUM($D42:K42)>0,0,IF(K$25>K40,K40,0))),0)<0,0,(IF(SUM($D42:K42)>0,0,IF(K$25>K40,K40,0))))) -> 0 | ... AOQ42: =IF(SUM($D$35:AOP35)=0,0,IF(IF(AOQ41>0,AOQ41-(IF(SUM($D42:AOP42)>0,0,IF(AOP$25>AOP40,AOP40,0))),0)<0,0,(IF(SUM($D42:AOP42)>0,0,IF(AOP$25>AOP40,AOP40,0))))) -> 0
B43: Periodo | C43: =SUM(D43:AOQ43) -> 645 | D43: =IF(D42>0,D$17,0) -> 0 | E43: =IF(E42>0,E$17,0) -> 0 | F43: =IF(F42>0,F$17,0) -> 0 | G43: =IF(G42>0,G$17,0) -> 0 | H43: =IF(H42>0,H$17,0) -> 0 | I43: =IF(I42>0,I$17,0) -> 0 | J43: =IF(J42>0,J$17,0) -> 0 | K43: =IF(K42>0,K$17,0) -> 0 | ... AOQ43: =IF(AOQ42>0,AOQ$17,0) -> 0
B44: Numero de periodos | C44: =SUM(D44:AOQ44) -> 56 | D44: 0 | E44: =IF(E42>0,SUM($D$18:D18),0) -> 0 | F44: =IF(F42>0,SUM($D$18:E18),0) -> 0 | G44: =IF(G42>0,SUM($D$18:F18),0) -> 0 | H44: =IF(H42>0,SUM($D$18:G18),0) -> 0 | I44: =IF(I42>0,SUM($D$18:H18),0) -> 0 | J44: =IF(J42>0,SUM($D$18:I18),0) -> 0 | K44: =IF(K42>0,SUM($D$18:J18),0) -> 0 | L44: =IF(L42>0,SUM($D$18:K18),0) -> 0 | ... AOQ44: =IF(AOQ42>0,SUM($D$18:AOP18),0) -> 0
...

Sheet Auxiliar
B2: Catálogos Entrevista | G2: Hoja de Cliente
B4: Edad de Retiro | D4: Género | F4: 2 | G4: =IF('Cálculos y Supuestos Edo.Res'!H10<=10%,IF('Cálculos y Supuestos Edo.Res'!C23>'Cálculos y Supuestos Edo.Res'!C25,"Tu nivel de gastos está excedido en GASTOS BÁSICOS"),IF('Cálculos y Supuestos Edo.Res'!C25>'Cálculos y Supuestos Edo.Res'!C23,"Tu nivel de gastos está excedido en OBLIGACIONES","")) | P4: =IF(G4="","NO BORRAR","") -> NO BORRAR | R4: Edad Venta de Activos
B5: =IF('Entrevista Patrimonio F.'!E9+1>80,"",'Entrevista Patrimonio F.'!E9+1) -> 51 | D5: Hombre | F5: 3 | G5: Para gráfica Ingresos vs. Gastos | P5: =IF(G5="","NO BORRAR","") | R5: =IF(EdaddeRetiro+1>80,"",EdaddeRetiro) -> 60
B6: =IF(B5<>"",IF(B5+1>80,"",B5+1),"") -> 52 | D6: Mujer | I6: Obligaciones | J6: Gastos Básicos | K6: Ahorro | R6: =IF(R5<>"",IF(R5+1>89,"",R5+1),"") -> 61
B7: =IF(B6<>"",IF(B6+1>80,"",B6+1),"") -> 53 | D7: Otro | G7: Actual | I7: ='Cálculos y Supuestos Edo.Res'!D25 -> 0.18181818 | J7: ='Cálculos y Supuestos Edo.Res'!D23 -> 0.36363636 | K7: ='Cálculos y Supuestos Edo.Res'!H10 -> 0.45454545 | R7: =IF(R6<>"",IF(R6+1>89,"",R6+1),"") -> 62
B8: =IF(B7<>"",IF(B7+1>80,"",B7+1),"") -> 54 | D8: Prefiero no contestar | G8: Objetivo mínimo de ahorro | I8: 0.5 | J8: 0.4 | K8: 0.1 | R8: =IF(R7<>"",IF(R7+1>89,"",R7+1),"") -> 63
B9: =IF(B8<>"",IF(B8+1>80,"",B8+1),"") -> 55 | F9: 4 | G9: ="Actualmente tienes cubierto "&TEXT('Cálculos y Supuestos Edo.Res'!G15,"###.#0")&" meses de tus gastos básicos. "&IF('Cálculos y Supuestos Edo.Res'!G15>=4,"Tu reserva está EXCEDIDA",IF('Cálculos y Supuestos Edo.Res'!G15<3,"Es necesario incrementar tu reserva.","Tienes un nivel de reserva suficiente.")) -> Actualmente tienes cubierto 5.0 meses de tus gastos básicos. Tu reserva está EXCEDIDA | P9: =IF(G9="","NO BORRAR","") | R9: =IF(R8<>"",IF(R8+1>89,"",R8+1),"") -> 64
B10: =IF(B9<>"",IF(B9+1>80,"",B9+1),"") -> 56 | F10: 5 | G10: =CONCATENATE('Cálculos y Supuestos Edo.Res'!G16," ",'Cálculos y Supuestos Edo.Res'!G19) -> Excedido 50000 | P10: =IF(G10="","NO BORRAR","") | R10: =IF(R9<>"",IF(R9+1>89,"",R9+1),"") -> 65
B11: =IF(B10<>"",IF(B10+1>80,"",B10+1),"") -> 57 | D11: Ocupación Actual | F11: 6 | G11: ="Para cubrir 3 meses de tus gastos = "&TEXT('Cálculos y Supuestos Edo.Res'!G14,"$###,###,###") -> Para cubrir 3 meses de tus gastos = $120,000 | P11: =IF(G11="","NO BORRAR","") | R11: =IF(R10<>"",IF(R10+1>89,"",R10+1),"") -> 66
B12: =IF(B11<>"",IF(B11+1>80,"",B11+1),"") -> 58 | D12: Asalariado | F12: 7 | G12: ="Considerando tu patrimonio financiero actual, puedes cubrir tus gastos totales anuales por "&TEXT('Cálculos y Supuestos Edo.Res'!G23,"#0.##")&" años." -> Considerando tu patrimonio financiero actual, puedes cubrir tus gastos totales anuales por 2.92 años. | P12: =IF(G12="","NO BORRAR","") | R12: =IF(R11<>"",IF(R11+1>89,"",R11+1),"") -> 67
B13: =IF(B12<>"",IF(B12+1>80,"",B12+1),"") -> 59 | D13: Independiente | F13: 8 | G13: ="Tienes tus gastos cubiertos hasta los " &ROUND('Cálculos y Supuestos Edo.Res'!G27,0)&" años de edad." -> Tienes tus gastos cubiertos hasta los 53 años de edad. | P13: =IF(G13="","NO BORRAR","") | R13: =IF(R12<>"",IF(R12+1>89,"",R12+1),"") -> 68
B14: =IF(B13<>"",IF(B13+1>80,"",B13+1),"") -> 60 | D14: Empresario | F14: 9 | G14: =IF('Cálculos y Supuestos Edo.Res'!G23<1,"POR DEBAJO DEL PROMEDIO",IF(AND('Cálculos y Supuestos Edo.Res'!G23>=1,'Cálculos y Supuestos Edo.Res'!G23<3),"POR ARRIBA DEL PROMEDIO",IF(AND('Cálculos y Supuestos Edo.Res'!G23>=3,'Cálculos y Supuestos Edo.Res'!G23<5),"RICO","ACAUDALADO"))) -> POR ARRIBA DEL PROMEDIO | P14: =IF(G14="","NO BORRAR","") | R14: =IF(R13<>"",IF(R13+1>89,"",R13+1),"") -> 69
B15: =IF(B14<>"",IF(B14+1>80,"",B14+1),"") -> 61 | F15: 10 | G15: ="Te encuentras en un nivel "&G14&". "&" "&G16 -> Te encuentras en un nivel POR ARRIBA DEL PROMEDIO. Incrementa tu riqueza para alcanzar alguna meta personal. | P15: =IF(G15="","NO BORRAR","") | R15: =IF(R14<>"",IF(R14+1>89,"",R14+1),"") -> 70
B16: =IF(B15<>"",IF(B15+1>80,"",B15+1),"") -> 62 | F16: 11 | G16: =IF(G14="POR DEBAJO DEL PROMEDIO","Incrementa tu riqueza para cubrir al menos un año de tus gastos básicos.",IF(OR(G14="POR ARRIBA DEL PROMEDIO",G14="RICO",G14="ACAUDALADO"),"Incrementa tu riqueza para alcanzar alguna meta personal.","")) -> Incrementa tu riqueza para alcanzar alguna meta personal. | P16: =IF(G16="","NO BORRAR","") | R16: =IF(R15<>"",IF(R15+1>89,"",R15+1),"") -> 71
B17: =IF(B16<>"",IF(B16+1>80,"",B16+1),"") -> 63 | D17: Sí/No | F17: 12 | G17: Gastos totales al año | P17: =IF(G17="","NO BORRAR","") | R17: =IF(R16<>"",IF(R16+1>89,"",R16+1),"") -> 72
B18: =IF(B17<>"",IF(B17+1>80,"",B17+1),"") -> 64 | D18: Sí | F18: 13 | G18: =IF(G14="POR DEBAJO DEL PROMEDIO","Meta al menos 1 año de gastos :"&TEXT(J18,"$###,###,###"),IF(OR(G14="POR ARRIBA DEL PROMEDIO",G14="RICO",G14="ACAUDALADO"),"Alcanza una meta personal","")) -> Alcanza una meta personal | J18: ='Cálculos y Supuestos Edo.Res'!C26*12 -> 720000 | P18: =IF(G18="","NO BORRAR","") | R18: =IF(R17<>"",IF(R17+1>89,"",R17+1),"") -> 73
B19: =IF(B18<>"",IF(B18+1>80,"",B18+1),"") -> 65 | D19: No | F19: 14 | G19: Para gráfica Nivel de Riqueza | P19: =IF(G19="","NO BORRAR","") | R19: =IF(R18<>"",IF(R18+1>89,"",R18+1),"") -> 74
B20: =IF(B19<>"",IF(B19+1>80,"",B19+1),"") -> 66 | H20: Por debajo | I20: Por arriba | J20: Rico | K20: Acaudalado | R20: =IF(R19<>"",IF(R19+1>89,"",R19+1),"") -> 75
B21: =IF(B20<>"",IF(B20+1>80,"",B20+1),"") -> 67 | G21: Referencia | H21: 1 | I21: 2 | J21: 1 | K21: 1 | P21: =IF(G21="","NO BORRAR","") | R21: =IF(R20<>"",IF(R20+1>89,"",R20+1),"") -> 76
B22: =IF(B21<>"",IF(B21+1>80,"",B21+1),"") -> 68 | D22: Periodicidad | G22: Mi nivel | H22: =MIN('Cálculos y Supuestos Edo.Res'!G23,5) -> 2.9166667 | P22: =IF(G22="","NO BORRAR","") | R22: =IF(R21<>"",IF(R21+1>89,"",R21+1),"") -> 77
B23: =IF(B22<>"",IF(B22+1>80,"",B22+1),"") -> 69 | D23: Mensual | F23: 15 | G23: Para gráfica mensualidad retiro sin Capital humano ni rentas | P23: =IF(G23="","NO BORRAR","") | R23: =IF(R22<>"",IF(R22+1>89,"",R22+1),"") -> 78
B24: =IF(B23<>"",IF(B23+1>80,"",B23+1),"") -> 70 | D24: Trimestral | H24: Afore | I24: Voluntario | J24: Ley 73 | R24: =IF(R23<>"",IF(R23+1>89,"",R23+1),"") -> 79
B25: =IF(B24<>"",IF(B24+1>80,"",B24+1),"") -> 71 | D25: Semestral | G25: Calidad de vida | H25: ='Cálculos y Supuestos Edo.Res'!C13 -> 50000 | R25: =IF(R24<>"",IF(R24+1>89,"",R24+1),"") -> 80
B26: =IF(B25<>"",IF(B25+1>80,"",B25+1),"") -> 72 | D26: Anual | G26: Mis esquemas | H26: =+'Cálculos y Supuestos Edo.Res'!G30 -> 3551.5588 | I26: ='Cálculos y Supuestos Edo.Res'!G31 -> 0 | J26: =+'Cálculos y Supuestos Edo.Res'!G32 -> 35000 | R26: =IF(R25<>"",IF(R25+1>89,"",R25+1),"") -> 81
B27: =IF(B26<>"",IF(B26+1>80,"",B26+1),"") -> 73 | F27: 16 | G27: ="Total de mensualidad en retiro: "&TEXT('Cálculos y Supuestos Edo.Res'!G33,"$ ###,###,###") -> Total de mensualidad en retiro: $ 38,552 | P27: =IF(G27="","NO BORRAR","") | R27: =IF(R26<>"",IF(R26+1>89,"",R26+1),"") -> 82
B28: =IF(B27<>"",IF(B27+1>80,"",B27+1),"") -> 74 | F28: 17 | G28: ="Tienes un avance del "&TEXT('Cálculos y Supuestos Edo.Res'!G34,"##%")&" de tu calidad de vida en edad de retiro." -> Tienes un avance del 77% de tu calidad de vida en edad de retiro. | P28: =IF(G28="","NO BORRAR","") | R28: =IF(R27<>"",IF(R27+1>89,"",R27+1),"") -> 83
B29: =IF(B28<>"",IF(B28+1>80,"",B28+1),"") -> 75 | F29: 18 | G29: ="Total de ingreso mensual en retiro :" -> Total de ingreso mensual en retiro : | I29: ='Cálculos y Supuestos Edo.Res'!G44 -> 48551.559 | P29: =IF(G29="","NO BORRAR","") | R29: =IF(R28<>"",IF(R28+1>89,"",R28+1),"") -> 84
B30: =IF(B29<>"",IF(B29+1>80,"",B29+1),"") -> 76 | F30: 19 | G30: =IF('Cálculos y Supuestos Edo.Res'!G53<-100,"DÉFICIT",IF('Cálculos y Supuestos Edo.Res'!G53>100,"SUPERÁVIT",IF(ABS('Cálculos y Supuestos Edo.Res'!G53)<=100,"EQUILIBRIO"))) -> SUPERÁVIT | P30: =IF(G30="","NO BORRAR","") | R30: =IF(R29<>"",IF(R29+1>89,"",R29+1),"") -> 85
B31: =IF(B30<>"",IF(B30+1>80,"",B30+1),"") -> 77 | F31: 20 | G31: =IF('Cálculos y Supuestos Edo.Res'!G44<'Cálculos y Supuestos Edo.Res'!C13,"Tendrías un faltante mensual de:",IF('Cálculos y Supuestos Edo.Res'!G44>='Cálculos y Supuestos Edo.Res'!C13,"Tu calidad de vida está cubierta")) -> Tendrías un faltante mensual de: | I31: =IF('Cálculos y Supuestos Edo.Res'!G44<'Cálculos y Supuestos Edo.Res'!C13,'Cálculos y Supuestos Edo.Res'!G44-'Cálculos y Supuestos Edo.Res'!C13,"") -> -1448.4412 | P31: =IF(G31="","NO BORRAR","") | R31: =IF(R30<>"",IF(R30+1>89,"",R30+1),"") -> 86
B32: =IF(B31<>"",IF(B31+1>80,"",B31+1),"") -> 78 | F32: 21 | G32: ="Tienes un avance del "&TEXT(K32,"##%")&" de tu calidad de vida en edad de retiro." -> Tienes un avance del 97% de tu calidad de vida en edad de retiro. | K32: =I29/'Cálculos y Supuestos Edo.Res'!C13 -> 0.97103118 | P32: =IF(G32="","NO BORRAR","") | R32: =IF(R31<>"",IF(R31+1>89,"",R31+1),"") -> 87
B33: =IF(B32<>"",IF(B32+1>80,"",B32+1),"") -> 79 | F33: 22 | G33: ="Si ahorras durante "&TEXT('Cálculos y Supuestos Edo.Res'!C8-'Cálculos y Supuestos Edo.Res'!C7,"#0")&" años (años hasta tu edad de retiro) puedes incrementar tus posibilidades al momento del retiro." -> Si ahorras durante 10 años (años hasta tu edad de retiro) puedes incrementar tus posibilidades al momento del retiro. | P33: =IF(G33="","NO BORRAR","") | R33: =IF(R32<>"",IF(R32+1>89,"",R32+1),"") -> 88
B34: =IF(B33<>"",IF(B33+1>80,"",B33+1),"") -> 80 | F34: 23 | G34: No es imperante que cuentes con un Seguro de Vida. | P34: =IF(G34="","NO BORRAR","") | R34: =IF(R33<>"",IF(R33+1>89,"",R33+1),"") -> 89
